Loaded 8000 rollouts
Loaded 1999 rollouts
Traceback (most recent call last):
  File "/home/aurora/handful-of-trials-pytorch/dynamics_model/new_model/train.py", line 174, in <module>
    main(sys.argv[1])
  File "/home/aurora/handful-of-trials-pytorch/dynamics_model/new_model/train.py", line 103, in main
    model = MaskedDynamicsEnsemble(cfg).to(device)
  File "/home/aurora/anaconda3/envs/pusht/lib/python3.10/site-packages/torch/nn/modules/module.py", line 927, in to
    return self._apply(convert)
  File "/home/aurora/anaconda3/envs/pusht/lib/python3.10/site-packages/torch/nn/modules/module.py", line 579, in _apply
    module._apply(fn)
  File "/home/aurora/anaconda3/envs/pusht/lib/python3.10/site-packages/torch/nn/modules/module.py", line 579, in _apply
    module._apply(fn)
  File "/home/aurora/anaconda3/envs/pusht/lib/python3.10/site-packages/torch/nn/modules/module.py", line 579, in _apply
    module._apply(fn)
  File "/home/aurora/anaconda3/envs/pusht/lib/python3.10/site-packages/torch/nn/modules/module.py", line 602, in _apply
    param_applied = fn(param)
  File "/home/aurora/anaconda3/envs/pusht/lib/python3.10/site-packages/torch/nn/modules/module.py", line 925, in convert
    return t.to(device, dtype if t.is_floating_point() or t.is_complex() else None, non_blocking)
RuntimeError: CUDA error: out of memory
CUDA kernel errors might be asynchronously reported at some other API call,so the stacktrace below might be incorrect.
For debugging consider passing CUDA_LAUNCH_BLOCKING=1.